Workbook

Sheet Student_Data
A1: Student_ID | B1: Full_Name | C1: Gender | D1: Class | E1: Section | F1: City | G1: Maths | H1: Science | I1: English | J1: Hindi | K1: Social_Studies | L1: Total | M1: Percentage | N1: Attendance | O1: Status
A2: STD-1001 | B2: Priya Choudhary | C2: Male | D2: 10 | E2: A | F2: Chandigarh | G2: 45 | H2: 97 | I2: 58 | J2: 76 | K2: 71 | L2: 347 | M2: 69.4 | N2: 84 | O2: Pass
A3: STD-1002 | B3: Aarav Verma | C3: Male | D3: 7 | E3: C | F3: Kolkata | G3: 89 | H3: 83 | I3: 96 | J3: 54 | K3: 57 | L3: 379 | M3: 75.8 | N3: 89 | O3: Pass
A4: STD-1003 | B4: Sai Iyer | C4: Male | D4: 8 | E4: C | F4: Kolkata | G4: 48 | H4: 53 | I4: 61 | J4: 57 | K4: 81 | L4: 300 | M4: 60 | N4: 86 | O4: Pass
A5: STD-1004 | B5: Ananya Singh | C5: Female | D5: 8 | E5: C | F5: Kolkata | G5: 84 | H5: 56 | I5: 72 | J5: 92 | K5: 68 | L5: 372 | M5: 74.4 | N5: 84 | O5: Pass
A6: STD-1005 | B6: Shreya Kulkarni | C6: Male | D6: 8 | E6: C | F6: Chandigarh | G6: 71 | H6: 48 | I6: 54 | J6: 79 | K6: 92 | L6: 344 | M6: 68.8 | N6: 80 | O6: Pass
A7: STD-1006 | B7: Aarav Kulkarni | C7: Female | D7: 7 | E7: C | F7: Delhi | G7: 97 | H7: 44 | I7: 81 | J7: 69 | K7: 57 | L7: 348 | M7: 69.6 | N7: 66 | O7: Pass
A8: STD-1007 | B8: Meera Gupta | C8: Male | D8: 9 | E8: C | F8: Lucknow | G8: 93 | H8: 100 | I8: 58 | J8: 46 | K8: 67 | L8: 364 | M8: 72.8 | N8: 74 | O8: Pass
A9: STD-1008 | B9: Kavya Gupta | C9: Male | D9: 7 | E9: C | F9: Bhopal | G9: 63 | H9: 99 | I9: 44 | J9: 51 | K9: 59 | L9: 316 | M9: 63.2 | N9: 66 | O9: Pass
A10: STD-1009 | B10: Vivaan Verma | C10: Male | D10: 9 | E10: B | F10: Kolkata | G10: 81 | H10: 62 | I10: 65 | J10: 47 | K10: 57 | L10: 312 | M10: 62.4 | N10: 73 | O10: Pass
A11: STD-1010 | B11: Ananya Banerjee | C11: Female | D11: 10 | E11: A | F11: Kolkata | G11: 74 | H11: 63 | I11: 66 | J11: 60 | K11: 90 | L11: 353 | M11: 70.6 | N11: 88 | O11: Pass
A12: STD-1011 | B12: Aditya Choudhary | C12: Male | D12: 7 | E12: C | F12: Chandigarh | G12: 51 | H12: 40 | I12: 43 | J12: 99 | K12: 45 | L12: 278 | M12: 55.6 | N12: 98 | O12: Pass
A13: STD-1012 | B13: Priya Patel | C13: Female | D13: 6 | E13: A | F13: Jaipur | G13: 71 | H13: 43 | I13: 97 | J13: 41 | K13: 57 | L13: 309 | M13: 61.8 | N13: 75 | O13: Pass
... A501: STD-1500 | B501: Priya Choudhary | C501: Female | D501: 7 | E501: A | F501: Delhi | G501: 66 | H501: 54 | I501: 81 | J501: 44 | K501: 61 | L501: 306 | M501: 61.2 | N501: 71 | O501: Pass

Sheet Questions Answers
A1: Questions | B1: Answers
A2: 1. Find the total number of students in the dataset. | B2: =COUNTA(Student_Data!A2:A501) -> 500
A3: 2. Count how many students belong to each Class. | B3: Class 10: 107 | Class 6: 98 | Class 7: 107 | Class 8: 88 | Class 9: 100
A4: 3. Identify how many students are from each City. | B4: Bhopal: 64 | Chandigarh: 69 | Delhi: 55 | Jaipur: 66 | Kolkata: 64 | Lucknow: 65 | Mumbai: 64 | Patna: 53
A5: 4. Count students who scored more than 75 marks in Maths. | B5: =COUNTIF(Student_Data!G2:G501, ">75") -> 207
A6: 5. Find how many students have Attendance greater than 90%. | B6: =COUNTIF(Student_Data!N2:N501, ">90") -> 135
A7: 6. Count students who are Female and studying in Class 10. | B7: =COUNTIFS(Student_Data!C2:C501, "Female", Student_Data!D2:D501, 10) -> 59
A8: 7. Find the number of students who passed but have Attendance below 75%. | B8: =COUNTIFS(Student_Data!O2:O501, "Pass", Student_Data!N2:N501, "<75") -> 169
A9: 8. Count students who scored above 80 in both Maths and Science. | B9: =COUNTIFS(Student_Data!G2:G501, ">80", Student_Data!H2:H501, ">80") -> 51
A10: 9. Identify how many students belong to Section A in Class 9. | B10: =COUNTIFS(Student_Data!E2:E501, "A", Student_Data!D2:D501, 9) -> 38
A11: 10. Calculate the total marks obtained by students from Delhi. | B11: =SUMIF(Student_Data!F2:F501, "Delhi", Student_Data!L2:L501) -> 19058
A12: 11. Find total Maths marks for students of Class 8. | B12: =SUMIF(Student_Data!D2:D501, 8, Student_Data!G2:G501) -> 6288
A13: 12. Calculate total marks of Female students from Mumbai. | B13: =SUMIFS(Student_Data!L2:L501, Student_Data!C2:C501, "Female", Student_Data!F2:F501, "Mumbai") -> 10649
A14: 13. Find the total attendance of students in Section B. | B14: =SUMIF(Student_Data!E2:E501, "B", Student_Data!N2:N501) -> 13512
A15: 14. Calculate the average percentage of students in Class 10. | B15: =AVERAGEIF(Student_Data!D2:D501, 10, Student_Data!M2:M501) -> 70.237383
A16: 15. Find average marks in English for Male students. | B16: =AVERAGEIF(Student_Data!C2:C501, "Male", Student_Data!I2:I501) -> 70.036
A17: 16. Calculate average percentage of students from Jaipur. | B17: =AVERAGEIF(Student_Data!F2:F501, "Jaipur", Student_Data!M2:M501) -> 71.312121
A18: 17. Find average attendance of students who passed. | B18: =AVERAGEIF(Student_Data!O2:O501, "Pass", Student_Data!N2:N501) -> 80.549098
A19: 18. Categorize students as “Topper” if percentage is above 85, otherwise “Average”. | B19: =COUNTIF(Student_Data!M2:M501, ">85") & " Toppers, " & COUNTIF(Student_Data!M2:M501, "<=85") & " Average" -> 6 Toppers, 494 Average
A20: 19. Identify students with low attendance (below 70%). | B20: =IFERROR(__xludf.DUMMYFUNCTION("IFERROR(TEXTJOIN("", "", TRUE, FILTER(Student_Data!B2:B501, Student_Data!N2:N501<70)), ""None"")"),"Aarav Kulkarni, Kavya Gupta, Sai Verma, Pooja Jain, Rohan Singh, Karan Iyer, Rahul Singh, Shreya Verma, Kavya Kulkarni, Tanvi Choudhary, Priya Jain, Aditya Iyer, Karan Kulkarni, Shreya Singh, Vivaan Verma, Karan Sharma, Karan Nair, Kavya Yadav, Sneha Yada"&"v, Pooja Verma, Sneha Verma, Sai Yadav, Pooja Kulkarni, Priya Banerjee, Ananya Choudhary, Neha Singh, Shreya Jain, Rohan Gupta, Ishita Nair, Simran Jain, Ananya Yadav, Aditya Choudhary, Ritika Verma, Vivaan Iyer, Sai Jain, Aarav Yadav, Ritika Verma, Anany"&"a Yadav, Tanvi Verma, Aarav Iyer, Kavya Jain, Priya Iyer, Meera Singh, Aditya Sharma, Rahul Sharma, Meera Jain, Ishita Sharma, Vivaan Kaur, Ritika Gupta, Kavya Patel, Aarav Choudhary, Pooja Iyer, Aditya Das, Kavya Nair, Ritika Das, Tanvi Patel, Ritika Das"&", Aditya Sharma, Meera Yadav, Simran Nair, Priya Reddy, Aditya Kulkarni, Sai Kaur, Priya Jain, Ananya Jain, Sneha Nair, Priya Choudhary, Ananya Das, Shreya Choudhary, Pooja Iyer, Sai Das, Aditya Kulkarni, Ishita Banerjee, Rohan Jain, Arjun Kaur, Vivaan Si"&"ngh, Karan Das, Sai Choudhary, Pooja Sharma, Tanvi Gupta, Aarav Singh, Shreya Singh, Ananya Choudhary, Sneha Verma, Arjun Singh, Shreya Kulkarni, Priya Verma, Pooja Verma, Arjun Sharma, Arjun Banerjee, Priya Jain, Karan Kulkarni, Shreya Das, Ritika Das, A"&"ditya Banerjee, Sneha Jain, Sneha Singh, Karan Sharma, Arjun Yadav, Aarav Verma, Meera Kulkarni, Sneha Reddy, Ritika Banerjee, Pooja Kulkarni, Simran Singh, Tanvi Das, Neha Das, Pooja Kulkarni, Kavya Verma, Ananya Banerjee, Vivaan Banerjee, Pooja Yadav, K"&"avya Iyer, Sneha Kaur, Tanvi Choudhary, Aditya Banerjee, Meera Banerjee, Kavya Iyer") -> Aarav Kulkarni, Kavya Gupta, Sai Verma, Pooja Jain, Rohan Singh, Karan Iyer, Rahul Singh, Shreya Verma, Kavya Kulkarni, Tanvi Choudhary, Priya Jain, Aditya Iyer, Karan Kulkarni, Shreya Singh, Vivaan Verma, Karan Sharma, Karan Nair, Kavya Yadav, Sneha Yadav, Pooja Verma, Sneha Verma, Sai Yadav, Pooja Kulkarni, Priya Banerjee, Ananya Choudhary, Neha Singh, Shreya Jain, Rohan Gupta, Ishita Nair, Simran Jain, Ananya Yadav, Aditya Choudhary, Ritika Verma, Vivaan Iyer, Sai Jain, Aarav Yadav, Ritika Verma, Ananya Yadav, Tanvi Verma, Aarav Iyer, Kavya Jain, Priya Iyer, Meera Singh, Aditya Sharma, Rahul Sharma, Meera Jain, Ishita Sharma, Vivaan Kaur, Ritika Gupta, Kavya Patel, Aarav Choudhary, Pooja Iyer, Aditya Das, Kavya Nair, Ritika Das, Tanvi Patel, Ritika Das, Aditya Sharma, Meera Yadav, Simran Nair, Priya Reddy, Aditya Kulkarni, Sai Kaur, Priya Jain, Ananya Jain, Sneha Nair, Priya Choudhary, Ananya Das, Shreya Choudhary, Pooja Iyer, Sai Das, Aditya Kulkarni, Ishita Banerjee, Rohan Jain, Arjun Kaur, Vivaan Singh, Karan Das, Sai Choudhary, Pooja Sharma, Tanvi Gupta, Aarav Singh, Shreya Singh, Ananya Choudhary, Sneha Verma, Arjun Singh, Shreya Kulkarni, Priya Verma, Pooja Verma, Arjun Sharma, Arjun Banerjee, Priya Jain, Karan Kulkarni, Shreya Das, Ritika Das, Aditya Banerjee, Sneha Jain, Sneha Singh, Karan Sharma, Arjun Yadav, Aarav Verma, Meera Kulkarni, Sneha Reddy, Ritika Banerjee, Pooja Kulkarni, Simran Singh, Tanvi Das, Neha Das, Pooja Kulkarni, Kavya Verma, Ananya Banerjee, Vivaan Banerjee, Pooja Yadav, Kavya Iyer, Sneha Kaur, Tanvi Choudhary, Aditya Banerjee, Meera Banerjee, Kavya Iyer
A21: 20. Flag students who failed in any subject (marks below 40 in any subject). | B21: =IFERROR(__xludf.DUMMYFUNCTION("IFERROR(TEXTJOIN("", "", TRUE, FILTER(Student_Data!B2:B501, (Student_Data!G2:G501<40)+(Student_Data!H2:H501<40)+(Student_Data!I2:I501<40)+(Student_Data!J2:J501<40)+(Student_Data!K2:K501<40)>0)), ""None"")"),"None") -> None
A22: 21. Retrieve full details of a student using their Student ID. | B22: =IFERROR(__xludf.DUMMYFUNCTION("TEXTJOIN("" | "", TRUE, FILTER(Student_Data!A2:O501, Student_Data!A2:A501=""STD-1001""))"),"STD-1001 | Priya Choudhary | Male | 10 | A | Chandigarh | 45 | 97 | 58 | 76 | 71 | 347 | 69.4 | 84 | Pass") -> STD-1001 | Priya Choudhary | Male | 10 | A | Chandigarh | 45 | 97 | 58 | 76 | 71 | 347 | 69.4 | 84 | Pass
A23: 22. Fetch the percentage of a specific student using their ID. | B23: =VLOOKUP("STD-1001", Student_Data!A2:O501, 13, FALSE) -> 69.4
A24: 23. Retrieve the city of a student using Student ID. | B24: =VLOOKUP("STD-1001", Student_Data!A2:O501, 6, FALSE) -> Chandigarh
A25: 24. Display all students whose percentage is greater than 80. | B25: =IFERROR(__xludf.DUMMYFUNCTION("IFERROR(TEXTJOIN("", "", TRUE, FILTER(Student_Data!B2:B501, Student_Data!M2:M501>80)), ""None"")"),"Karan Iyer, Shreya Singh, Karan Choudhary, Kavya Reddy, Arjun Banerjee, Rahul Choudhary, Neha Verma, Ishita Choudhary, Neha Choudhary, Priya Nair, Ritika Das, Sneha Nair, Priya Choudhary, Ishita Sharma, Aditya Kulkarni, Rohan Jain, Rohan Das, Karan Das, N"&"eha Das, Sai Das, Pooja Sharma, Ritika Sharma, Aarav Patel, Priya Verma, Pooja Verma, Arjun Banerjee, Ritika Patel, Shreya Das, Karan Sharma, Ritika Banerjee, Vivaan Gupta, Rahul Choudhary, Rohan Yadav, Priya Reddy, Aarav Gupta, Kavya Verma, Sai Patel, Ri"&"tika Yadav, Ritika Jain, Pooja Yadav, Simran Choudhary, Meera Iyer") -> Karan Iyer, Shreya Singh, Karan Choudhary, Kavya Reddy, Arjun Banerjee, Rahul Choudhary, Neha Verma, Ishita Choudhary, Neha Choudhary, Priya Nair, Ritika Das, Sneha Nair, Priya Choudhary, Ishita Sharma, Aditya Kulkarni, Rohan Jain, Rohan Das, Karan Das, Neha Das, Sai Das, Pooja Sharma, Ritika Sharma, Aarav Patel, Priya Verma, Pooja Verma, Arjun Banerjee, Ritika Patel, Shreya Das, Karan Sharma, Ritika Banerjee, Vivaan Gupta, Rahul Choudhary, Rohan Yadav, Priya Reddy, Aarav Gupta, Kavya Verma, Sai Patel, Ritika Yadav, Ritika Jain, Pooja Yadav, Simran Choudhary, Meera Iyer
A26: 25. Show only Female students from Class 9. | B26: =IFERROR(__xludf.DUMMYFUNCTION("IFERROR(TEXTJOIN("", "", TRUE, FILTER(Student_Data!B2:B501, Student_Data!C2:C501=""Female"", Student_Data!D2:D501=""9"")), ""None"")"),"Ananya Yadav, Arjun Reddy, Arjun Singh, Ishita Kulkarni, Sneha Gupta, Shreya Singh, Ananya Iyer, Karan Verma, Vivaan Gupta, Pooja Verma, Pooja Nair, Rahul Choudhary, Sai Sharma, Aarav Gupta, Sai Jain, Neha Kulkarni, Meera Kulkarni, Rahul Verma, Rahul Verm"&"a, Rahul Jain, Ananya Reddy, Kavya Das, Karan Verma, Sai Das, Kavya Jain, Karan Verma, Vivaan Singh, Ananya Nair, Meera Das, Rohan Nair, Sai Choudhary, Arjun Singh, Pooja Sharma, Aarav Singh, Priya Nair, Pooja Iyer, Pooja Verma, Simran Banerjee, Vivaan Na"&"ir, Vivaan Singh, Vivaan Banerjee, Kavya Jain, Neha Gupta, Priya Reddy, Rahul Das, Aarav Gupta, Ananya Jain, Kavya Singh, Vivaan Banerjee, Shreya Singh") -> Ananya Yadav, Arjun Reddy, Arjun Singh, Ishita Kulkarni, Sneha Gupta, Shreya Singh, Ananya Iyer, Karan Verma, Vivaan Gupta, Pooja Verma, Pooja Nair, Rahul Choudhary, Sai Sharma, Aarav Gupta, Sai Jain, Neha Kulkarni, Meera Kulkarni, Rahul Verma, Rahul Verma, Rahul Jain, Ananya Reddy, Kavya Das, Karan Verma, Sai Das, Kavya Jain, Karan Verma, Vivaan Singh, Ananya Nair, Meera Das, Rohan Nair, Sai Choudhary, Arjun Singh, Pooja Sharma, Aarav Singh, Priya Nair, Pooja Iyer, Pooja Verma, Simran Banerjee, Vivaan Nair, Vivaan Singh, Vivaan Banerjee, Kavya Jain, Neha Gupta, Priya Reddy, Rahul Das, Aarav Gupta, Ananya Jain, Kavya Singh, Vivaan Banerjee, Shreya Singh
A27: 26. Generate a summary showing average percentage for each Class. | B27: Class 10: 70.24% | Class 6: 70.47% | Class 7: 69.59% | Class 8: 67.91% | Class 9: 69.9%
A28: 27. Generate a report showing total students in each City. | B28: Bhopal: 64 | Chandigarh: 69 | Delhi: 55 | Jaipur: 66 | Kolkata: 64 | Lucknow: 65 | Mumbai: 64 | Patna: 53
A29: 28. Count how many unique cities are present in the dataset. | B29: {=COUNTA(UNIQUE(Student_Data!F2:F501))} -> 8
A30: 29. Identify if any student record has missing values. | B30: =IF(COUNTBLANK(Student_Data!A2:O501)>0, "Yes", "No") -> No
A31: 30. Create a report showing total number of Pass and Fail students. | B31: ="Pass: " & COUNTIF(Student_Data!O2:O501, "Pass") & " | Fail: " & COUNTIF(Student_Data!O2:O501, "Fail") -> Pass: 499 | Fail: 1

Sheet Q1
A1: {='Questions Answers'!A2} -> 1. Find the total number of students in the dataset.
A3: Total Students
A4: 500

Sheet Q2
A1: {='Questions Answers'!A3} -> 2. Count how many students belong to each Class.
A3: =IFERROR(__xludf.DUMMYFUNCTION("QUERY(Student_Data!A1:O1000, ""SELECT D, COUNT(A) WHERE A IS NOT NULL GROUP BY D LABEL D 'Class', COUNT(A) 'Student Count'"")"),"Class") -> Class | B3: =IFERROR(__xludf.DUMMYFUNCTION("""COMPUTED_VALUE"""),"Student Count") -> Student Count
A4: =IFERROR(__xludf.DUMMYFUNCTION("""COMPUTED_VALUE"""),"10") -> 10 | B4: =IFERROR(__xludf.DUMMYFUNCTION("""COMPUTED_VALUE"""),107.0) -> 107
A5: =IFERROR(__xludf.DUMMYFUNCTION("""COMPUTED_VALUE"""),"6") -> 6 | B5: =IFERROR(__xludf.DUMMYFUNCTION("""COMPUTED_VALUE"""),98.0) -> 98
A6: =IFERROR(__xludf.DUMMYFUNCTION("""COMPUTED_VALUE"""),"7") -> 7 | B6: =IFERROR(__xludf.DUMMYFUNCTION("""COMPUTED_VALUE"""),107.0) -> 107
A7: =IFERROR(__xludf.DUMMYFUNCTION("""COMPUTED_VALUE"""),"8") -> 8 | B7: =IFERROR(__xludf.DUMMYFUNCTION("""COMPUTED_VALUE"""),88.0) -> 88
A8: =IFERROR(__xludf.DUMMYFUNCTION("""COMPUTED_VALUE"""),"9") -> 9 | B8: =IFERROR(__xludf.DUMMYFUNCTION("""COMPUTED_VALUE"""),100.0) -> 100

Sheet Q3
A1: {='Questions Answers'!A4} -> 3. Identify how many students are from each City.
A3: =IFERROR(__xludf.DUMMYFUNCTION("QUERY(Student_Data!A1:O1000, ""SELECT F, COUNT(A) WHERE A IS NOT NULL GROUP BY F LABEL F 'City', COUNT(A) 'Student Count'"")"),"City") -> City | B3: =IFERROR(__xludf.DUMMYFUNCTION("""COMPUTED_VALUE"""),"Student Count") -> Student Count
A4: =IFERROR(__xludf.DUMMYFUNCTION("""COMPUTED_VALUE"""),"Bhopal") -> Bhopal | B4: =IFERROR(__xludf.DUMMYFUNCTION("""COMPUTED_VALUE"""),64.0) -> 64
A5: =IFERROR(__xludf.DUMMYFUNCTION("""COMPUTED_VALUE"""),"Chandigarh") -> Chandigarh | B5: =IFERROR(__xludf.DUMMYFUNCTION("""COMPUTED_VALUE"""),69.0) -> 69
A6: =IFERROR(__xludf.DUMMYFUNCTION("""COMPUTED_VALUE"""),"Delhi") -> Delhi | B6: =IFERROR(__xludf.DUMMYFUNCTION("""COMPUTED_VALUE"""),55.0) -> 55
A7: =IFERROR(__xludf.DUMMYFUNCTION("""COMPUTED_VALUE"""),"Jaipur") -> Jaipur | B7: =IFERROR(__xludf.DUMMYFUNCTION("""COMPUTED_VALUE"""),66.0) -> 66
A8: =IFERROR(__xludf.DUMMYFUNCTION("""COMPUTED_VALUE"""),"Kolkata") -> Kolkata | B8: =IFERROR(__xludf.DUMMYFUNCTION("""COMPUTED_VALUE"""),64.0) -> 64
A9: =IFERROR(__xludf.DUMMYFUNCTION("""COMPUTED_VALUE"""),"Lucknow") -> Lucknow | B9: =IFERROR(__xludf.DUMMYFUNCTION("""COMPUTED_VALUE"""),65.0) -> 65
A10: =IFERROR(__xludf.DUMMYFUNCTION("""COMPUTED_VALUE"""),"Mumbai") -> Mumbai | B10: =IFERROR(__xludf.DUMMYFUNCTION("""COMPUTED_VALUE"""),64.0) -> 64
A11: =IFERROR(__xludf.DUMMYFUNCTION("""COMPUTED_VALUE"""),"Patna") -> Patna | B11: =IFERROR(__xludf.DUMMYFUNCTION("""COMPUTED_VALUE"""),53.0) -> 53

Sheet Q4
A1: {='Questions Answers'!A5} -> 4. Count students who scored more than 75 marks in Maths.
A2: Answers: 207
A3: =IFERROR(__xludf.DUMMYFUNCTION("QUERY(Student_Data!A1:O1000, ""SELECT * WHERE G > 75"")"),"Student_ID") -> Student_ID | B3: =IFERROR(__xludf.DUMMYFUNCTION("""COMPUTED_VALUE"""),"Full_Name") -> Full_Name | C3: =IFERROR(__xludf.DUMMYFUNCTION("""COMPUTED_VALUE"""),"Gender") -> Gender | D3: =IFERROR(__xludf.DUMMYFUNCTION("""COMPUTED_VALUE"""),"Class") -> Class | E3: =IFERROR(__xludf.DUMMYFUNCTION("""COMPUTED_VALUE"""),"Section") -> Section | F3: =IFERROR(__xludf.DUMMYFUNCTION("""COMPUTED_VALUE"""),"City") -> City | G3: =IFERROR(__xludf.DUMMYFUNCTION("""COMPUTED_VALUE"""),"Maths") -> Maths | H3: =IFERROR(__xludf.DUMMYFUNCTION("""COMPUTED_VALUE"""),"Science") -> Science | I3: =IFERROR(__xludf.DUMMYFUNCTION("""COMPUTED_VALUE"""),"English") -> English | J3: =IFERROR(__xludf.DUMMYFUNCTION("""COMPUTED_VALUE"""),"Hindi") -> Hindi | K3: =IFERROR(__xludf.DUMMYFUNCTION("""COMPUTED_VALUE"""),"Social_Studies") -> Social_Studies | L3: =IFERROR(__xludf.DUMMYFUNCTION("""COMPUTED_VALUE"""),"Total") -> Total | M3: =IFERROR(__xludf.DUMMYFUNCTION("""COMPUTED_VALUE"""),"Percentage") -> Percentage | N3: =IFERROR(__xludf.DUMMYFUNCTION("""COMPUTED_VALUE"""),"Attendance") -> Attendance | O3: =IFERROR(__xludf.DUMMYFUNCTION("""COMPUTED_VALUE"""),"Status") -> Status
A4: =IFERROR(__xludf.DUMMYFUNCTION("""COMPUTED_VALUE"""),"STD-1002") -> STD-1002 | B4: =IFERROR(__xludf.DUMMYFUNCTION("""COMPUTED_VALUE"""),"Aarav Verma") -> Aarav Verma | C4: =IFERROR(__xludf.DUMMYFUNCTION("""COMPUTED_VALUE"""),"Male") -> Male | D4: =IFERROR(__xludf.DUMMYFUNCTION("""COMPUTED_VALUE"""),"7") -> 7 | E4: =IFERROR(__xludf.DUMMYFUNCTION("""COMPUTED_VALUE"""),"C") -> C | F4: =IFERROR(__xludf.DUMMYFUNCTION("""COMPUTED_VALUE"""),"Kolkata") -> Kolkata | G4: =IFERROR(__xludf.DUMMYFUNCTION("""COMPUTED_VALUE"""),89.0) -> 89 | H4: =IFERROR(__xludf.DUMMYFUNCTION("""COMPUTED_VALUE"""),83.0) -> 83 | I4: =IFERROR(__xludf.DUMMYFUNCTION("""COMPUTED_VALUE"""),96.0) -> 96 | J4: =IFERROR(__xludf.DUMMYFUNCTION("""COMPUTED_VALUE"""),54.0) -> 54 | K4: =IFERROR(__xludf.DUMMYFUNCTION("""COMPUTED_VALUE"""),57.0) -> 57 | L4: =IFERROR(__xludf.DUMMYFUNCTION("""COMPUTED_VALUE"""),379.0) -> 379 | M4: =IFERROR(__xludf.DUMMYFUNCTION("""COMPUTED_VALUE"""),75.8) -> 75.8 | N4: =IFERROR(__xludf.DUMMYFUNCTION("""COMPUTED_VALUE"""),89.0) -> 89 | O4: =IFERROR(__xludf.DUMMYFUNCTION("""COMPUTED_VALUE"""),"Pass") -> Pass
A5: =IFERROR(__xludf.DUMMYFUNCTION("""COMPUTED_VALUE"""),"STD-1004") -> STD-1004 | B5: =IFERROR(__xludf.DUMMYFUNCTION("""COMPUTED_VALUE"""),"Ananya Singh") -> Ananya Singh | C5: =IFERROR(__xludf.DUMMYFUNCTION("""COMPUTED_VALUE"""),"Female") -> Female | D5: =IFERROR(__xludf.DUMMYFUNCTION("""COMPUTED_VALUE"""),"8") -> 8 | E5: =IFERROR(__xludf.DUMMYFUNCTION("""COMPUTED_VALUE"""),"C") -> C | F5: =IFERROR(__xludf.DUMMYFUNCTION("""COMPUTED_VALUE"""),"Kolkata") -> Kolkata | G5: =IFERROR(__xludf.DUMMYFUNCTION("""COMPUTED_VALUE"""),84.0) -> 84 | H5: =IFERROR(__xludf.DUMMYFUNCTION("""COMPUTED_VALUE"""),56.0) -> 56 | I5: =IFERROR(__xludf.DUMMYFUNCTION("""COMPUTED_VALUE"""),72.0) -> 72 | J5: =IFERROR(__xludf.DUMMYFUNCTION("""COMPUTED_VALUE"""),92.0) -> 92 | K5: =IFERROR(__xludf.DUMMYFUNCTION("""COMPUTED_VALUE"""),68.0) -> 68 | L5: =IFERROR(__xludf.DUMMYFUNCTION("""COMPUTED_VALUE"""),372.0) -> 372 | M5: =IFERROR(__xludf.DUMMYFUNCTION("""COMPUTED_VALUE"""),74.4) -> 74.4 | N5: =IFERROR(__xludf.DUMMYFUNCTION("""COMPUTED_VALUE"""),84.0) -> 84 | O5: =IFERROR(__xludf.DUMMYFUNCTION("""COMPUTED_VALUE"""),"Pass") -> Pass
A6: =IFERROR(__xludf.DUMMYFUNCTION("""COMPUTED_VALUE"""),"STD-1006") -> STD-1006 | B6: =IFERROR(__xludf.DUMMYFUNCTION("""COMPUTED_VALUE"""),"Aarav Kulkarni") -> Aarav Kulkarni | C6: =IFERROR(__xludf.DUMMYFUNCTION("""COMPUTED_VALUE"""),"Female") -> Female | D6: =IFERROR(__xludf.DUMMYFUNCTION("""COMPUTED_VALUE"""),"7") -> 7 | E6: =IFERROR(__xludf.DUMMYFUNCTION("""COMPUTED_VALUE"""),"C") -> C | F6: =IFERROR(__xludf.DUMMYFUNCTION("""COMPUTED_VALUE"""),"Delhi") -> Delhi | G6: =IFERROR(__xludf.DUMMYFUNCTION("""COMPUTED_VALUE"""),97.0) -> 97 | H6: =IFERROR(__xludf.DUMMYFUNCTION("""COMPUTED_VALUE"""),44.0) -> 44 | I6: =IFERROR(__xludf.DUMMYFUNCTION("""COMPUTED_VALUE"""),81.0) -> 81 | J6: =IFERROR(__xludf.DUMMYFUNCTION("""COMPUTED_VALUE"""),69.0) -> 69 | K6: =IFERROR(__xludf.DUMMYFUNCTION("""COMPUTED_VALUE"""),57.0) -> 57 | L6: =IFERROR(__xludf.DUMMYFUNCTION("""COMPUTED_VALUE"""),348.0) -> 348 | M6: =IFERROR(__xludf.DUMMYFUNCTION("""COMPUTED_VALUE"""),69.6) -> 69.6 | N6: =IFERROR(__xludf.DUMMYFUNCTION("""COMPUTED_VALUE"""),66.0) -> 66 | O6: =IFERROR(__xludf.DUMMYFUNCTION("""COMPUTED_VALUE"""),"Pass") -> Pass
A7: =IFERROR(__xludf.DUMMYFUNCTION("""COMPUTED_VALUE"""),"STD-1007") -> STD-1007 | B7: =IFERROR(__xludf.DUMMYFUNCTION("""COMPUTED_VALUE"""),"Meera Gupta") -> Meera Gupta | C7: =IFERROR(__xludf.DUMMYFUNCTION("""COMPUTED_VALUE"""),"Male") -> Male | D7: =IFERROR(__xludf.DUMMYFUNCTION("""COMPUTED_VALUE"""),"9") -> 9 | E7: =IFERROR(__xludf.DUMMYFUNCTION("""COMPUTED_VALUE"""),"C") -> C | F7: =IFERROR(__xludf.DUMMYFUNCTION("""COMPUTED_VALUE"""),"Lucknow") -> Lucknow | G7: =IFERROR(__xludf.DUMMYFUNCTION("""COMPUTED_VALUE"""),93.0) -> 93 | H7: =IFERROR(__xludf.DUMMYFUNCTION("""COMPUTED_VALUE"""),100.0) -> 100 | I7: =IFERROR(__xludf.DUMMYFUNCTION("""COMPUTED_VALUE"""),58.0) -> 58 | J7: =IFERROR(__xludf.DUMMYFUNCTION("""COMPUTED_VALUE"""),46.0) -> 46 | K7: =IFERROR(__xludf.DUMMYFUNCTION("""COMPUTED_VALUE"""),67.0) -> 67 | L7: =IFERROR(__xludf.DUMMYFUNCTION("""COMPUTED_VALUE"""),364.0) -> 364 | M7: =IFERROR(__xludf.DUMMYFUNCTION("""COMPUTED_VALUE"""),72.8) -> 72.8 | N7: =IFERROR(__xludf.DUMMYFUNCTION("""COMPUTED_VALUE"""),74.0) -> 74 | O7: =IFERROR(__xludf.DUMMYFUNCTION("""COMPUTED_VALUE"""),"Pass") -> Pass
A8: =IFERROR(__xludf.DUMMYFUNCTION("""COMPUTED_VALUE"""),"STD-1009") -> STD-1009 | B8: =IFERROR(__xludf.DUMMYFUNCTION("""COMPUTED_VALUE"""),"Vivaan Verma") -> Vivaan Verma | C8: =IFERROR(__xludf.DUMMYFUNCTION("""COMPUTED_VALUE"""),"Male") -> Male | D8: =IFERROR(__xludf.DUMMYFUNCTION("""COMPUTED_VALUE"""),"9") -> 9 | E8: =IFERROR(__xludf.DUMMYFUNCTION("""COMPUTED_VALUE"""),"B") -> B | F8: =IFERROR(__xludf.DUMMYFUNCTION("""COMPUTED_VALUE"""),"Kolkata") -> Kolkata | G8: =IFERROR(__xludf.DUMMYFUNCTION("""COMPUTED_VALUE"""),81.0) -> 81 | H8: =IFERROR(__xludf.DUMMYFUNCTION("""COMPUTED_VALUE"""),62.0) -> 62 | I8: =IFERROR(__xludf.DUMMYFUNCTION("""COMPUTED_VALUE"""),65.0) -> 65 | J8: =IFERROR(__xludf.DUMMYFUNCTION("""COMPUTED_VALUE"""),47.0) -> 47 | K8: =IFERROR(__xludf.DUMMYFUNCTION("""COMPUTED_VALUE"""),57.0) -> 57 | L8: =IFERROR(__xludf.DUMMYFUNCTION("""COMPUTED_VALUE"""),312.0) -> 312 | M8: =IFERROR(__xludf.DUMMYFUNCTION("""COMPUTED_VALUE"""),62.4) -> 62.4 | N8: =IFERROR(__xludf.DUMMYFUNCTION("""COMPUTED_VALUE"""),73.0) -> 73 | O8: =IFERROR(__xludf.DUMMYFUNCTION("""COMPUTED_VALUE"""),"Pass") -> Pass
A9: =IFERROR(__xludf.DUMMYFUNCTION("""COMPUTED_VALUE"""),"STD-1014") -> STD-1014 | B9: =IFERROR(__xludf.DUMMYFUNCTION("""COMPUTED_VALUE"""),"Ananya Yadav") -> Ananya Yadav | C9: =IFERROR(__xludf.DUMMYFUNCTION("""COMPUTED_VALUE"""),"Female") -> Female | D9: =IFERROR(__xludf.DUMMYFUNCTION("""COMPUTED_VALUE"""),"9") -> 9 | E9: =IFERROR(__xludf.DUMMYFUNCTION("""COMPUTED_VALUE"""),"C") -> C | F9: =IFERROR(__xludf.DUMMYFUNCTION("""COMPUTED_VALUE"""),"Chandigarh") -> Chandigarh | G9: =IFERROR(__xludf.DUMMYFUNCTION("""COMPUTED_VALUE"""),78.0) -> 78 | H9: =IFERROR(__xludf.DUMMYFUNCTION("""COMPUTED_VALUE"""),92.0) -> 92 | I9: =IFERROR(__xludf.DUMMYFUNCTION("""COMPUTED_VALUE"""),58.0) -> 58 | J9: =IFERROR(__xludf.DUMMYFUNCTION("""COMPUTED_VALUE"""),42.0) -> 42 | K9: =IFERROR(__xludf.DUMMYFUNCTION("""COMPUTED_VALUE"""),69.0) -> 69 | L9: =IFERROR(__xludf.DUMMYFUNCTION("""COMPUTED_VALUE"""),339.0) -> 339 | M9: =IFERROR(__xludf.DUMMYFUNCTION("""COMPUTED_VALUE"""),67.8) -> 67.8 | N9: =IFERROR(__xludf.DUMMYFUNCTION("""COMPUTED_VALUE"""),85.0) -> 85 | O9: =IFERROR(__xludf.DUMMYFUNCTION("""COMPUTED_VALUE"""),"Pass") -> Pass
A10: =IFERROR(__xludf.DUMMYFUNCTION("""COMPUTED_VALUE"""),"STD-1017") -> STD-1017 | B10: =IFERROR(__xludf.DUMMYFUNCTION("""COMPUTED_VALUE"""),"Rohan Singh") -> Rohan Singh | C10: =IFERROR(__xludf.DUMMYFUNCTION("""COMPUTED_VALUE"""),"Male") -> Male | D10: =IFERROR(__xludf.DUMMYFUNCTION("""COMPUTED_VALUE"""),"6") -> 6 | E10: =IFERROR(__xludf.DUMMYFUNCTION("""COMPUTED_VALUE"""),"C") -> C | F10: =IFERROR(__xludf.DUMMYFUNCTION("""COMPUTED_VALUE"""),"Delhi") -> Delhi | G10: =IFERROR(__xludf.DUMMYFUNCTION("""COMPUTED_VALUE"""),90.0) -> 90 | H10: =IFERROR(__xludf.DUMMYFUNCTION("""COMPUTED_VALUE"""),77.0) -> 77 | I10: =IFERROR(__xludf.DUMMYFUNCTION("""COMPUTED_VALUE"""),48.0) -> 48 | J10: =IFERROR(__xludf.DUMMYFUNCTION("""COMPUTED_VALUE"""),79.0) -> 79 | K10: =IFERROR(__xludf.DUMMYFUNCTION("""COMPUTED_VALUE"""),71.0) -> 71 | L10: =IFERROR(__xludf.DUMMYFUNCTION("""COMPUTED_VALUE"""),365.0) -> 365 | M10: =IFERROR(__xludf.DUMMYFUNCTION("""COMPUTED_VALUE"""),73.0) -> 73 | N10: =IFERROR(__xludf.DUMMYFUNCTION("""COMPUTED_VALUE"""),61.0) -> 61 | O10: =IFERROR(__xludf.DUMMYFUNCTION("""COMPUTED_VALUE"""),"Pass") -> Pass
A11: =IFERROR(__xludf.DUMMYFUNCTION("""COMPUTED_VALUE"""),"STD-1019") -> STD-1019 | B11: =IFERROR(__xludf.DUMMYFUNCTION("""COMPUTED_VALUE"""),"Karan Iyer") -> Karan Iyer | C11: =IFERROR(__xludf.DUMMYFUNCTION("""COMPUTED_VALUE"""),"Male") -> Male | D11: =IFERROR(__xludf.DUMMYFUNCTION("""COMPUTED_VALUE"""),"6") -> 6 | E11: =IFERROR(__xludf.DUMMYFUNCTION("""COMPUTED_VALUE"""),"B") -> B | F11: =IFERROR(__xludf.DUMMYFUNCTION("""COMPUTED_VALUE"""),"Chandigarh") -> Chandigarh | G11: =IFERROR(__xludf.DUMMYFUNCTION("""COMPUTED_VALUE"""),83.0) -> 83 | H11: =IFERROR(__xludf.DUMMYFUNCTION("""COMPUTED_VALUE"""),60.0) -> 60 | I11: =IFERROR(__xludf.DUMMYFUNCTION("""COMPUTED_VALUE"""),95.0) -> 95 | J11: =IFERROR(__xludf.DUMMYFUNCTION("""COMPUTED_VALUE"""),99.0) -> 99 | K11: =IFERROR(__xludf.DUMMYFUNCTION("""COMPUTED_VALUE"""),66.0) -> 66 | L11: =IFERROR(__xludf.DUMMYFUNCTION("""COMPUTED_VALUE"""),403.0) -> 403 | M11: =IFERROR(__xludf.DUMMYFUNCTION("""COMPUTED_VALUE"""),80.6) -> 80.6 | N11: =IFERROR(__xludf.DUMMYFUNCTION("""COMPUTED_VALUE"""),65.0) -> 65 | O11: =IFERROR(__xludf.DUMMYFUNCTION("""COMPUTED_VALUE"""),"Pass") -> Pass
A12: =IFERROR(__xludf.DUMMYFUNCTION("""COMPUTED_VALUE"""),"STD-1021") -> STD-1021 | B12: =IFERROR(__xludf.DUMMYFUNCTION("""COMPUTED_VALUE"""),"Ishita Kulkarni") -> Ishita Kulkarni | C12: =IFERROR(__xludf.DUMMYFUNCTION("""COMPUTED_VALUE"""),"Female") -> Female | D12: =IFERROR(__xludf.DUMMYFUNCTION("""COMPUTED_VALUE"""),"9") -> 9 | E12: =IFERROR(__xludf.DUMMYFUNCTION("""COMPUTED_VALUE"""),"C") -> C | F12: =IFERROR(__xludf.DUMMYFUNCTION("""COMPUTED_VALUE"""),"Lucknow") -> Lucknow | G12: =IFERROR(__xludf.DUMMYFUNCTION("""COMPUTED_VALUE"""),88.0) -> 88 | H12: =IFERROR(__xludf.DUMMYFUNCTION("""COMPUTED_VALUE"""),65.0) -> 65 | I12: =IFERROR(__xludf.DUMMYFUNCTION("""COMPUTED_VALUE"""),57.0) -> 57 | J12: =IFERROR(__xludf.DUMMYFUNCTION("""COMPUTED_VALUE"""),52.0) -> 52 | K12: =IFERROR(__xludf.DUMMYFUNCTION("""COMPUTED_VALUE"""),53.0) -> 53 | L12: =IFERROR(__xludf.DUMMYFUNCTION("""COMPUTED_VALUE"""),315.0) -> 315 | M12: =IFERROR(__xludf.DUMMYFUNCTION("""COMPUTED_VALUE"""),63.0) -> 63 | N12: =IFERROR(__xludf.DUMMYFUNCTION("""COMPUTED_VALUE"""),98.0) -> 98 | O12: =IFERROR(__xludf.DUMMYFUNCTION("""COMPUTED_VALUE"""),"Pass") -> Pass
A13: =IFERROR(__xludf.DUMMYFUNCTION("""COMPUTED_VALUE"""),"STD-1023") -> STD-1023 | B13: =IFERROR(__xludf.DUMMYFUNCTION("""COMPUTED_VALUE"""),"Sneha Gupta") -> Sneha Gupta | C13: =IFERROR(__xludf.DUMMYFUNCTION("""COMPUTED_VALUE"""),"Male") -> Male | D13: =IFERROR(__xludf.DUMMYFUNCTION("""COMPUTED_VALUE"""),"10") -> 10 | E13: =IFERROR(__xludf.DUMMYFUNCTION("""COMPUTED_VALUE"""),"A") -> A | F13: =IFERROR(__xludf.DUMMYFUNCTION("""COMPUTED_VALUE"""),"Chandigarh") -> Chandigarh | G13: =IFERROR(__xludf.DUMMYFUNCTION("""COMPUTED_VALUE"""),77.0) -> 77 | H13: =IFERROR(__xludf.DUMMYFUNCTION("""COMPUTED_VALUE"""),93.0) -> 93 | I13: =IFERROR(__xludf.DUMMYFUNCTION("""COMPUTED_VALUE"""),90.0) -> 90 | J13: =IFERROR(__xludf.DUMMYFUNCTION("""COMPUTED_VALUE"""),84.0) -> 84 | K13: =IFERROR(__xludf.DUMMYFUNCTION("""COMPUTED_VALUE"""),46.0) -> 46 | L13: =IFERROR(__xludf.DUMMYFUNCTION("""COMPUTED_VALUE"""),390.0) -> 390 | M13: =IFERROR(__xludf.DUMMYFUNCTION("""COMPUTED_VALUE"""),78.0) -> 78 | N13: =IFERROR(__xludf.DUMMYFUNCTION("""COMPUTED_VALUE"""),75.0) -> 75 | O13: =IFERROR(__xludf.DUMMYFUNCTION("""COMPUTED_VALUE"""),"Pass") -> Pass
A14: =IFERROR(__xludf.DUMMYFUNCTION("""COMPUTED_VALUE"""),"STD-1025") -> STD-1025 | B14: =IFERROR(__xludf.DUMMYFUNCTION("""COMPUTED_VALUE"""),"Ananya Nair") -> Ananya Nair | C14: =IFERROR(__xludf.DUMMYFUNCTION("""COMPUTED_VALUE"""),"Male") -> Male | D14: =IFERROR(__xludf.DUMMYFUNCTION("""COMPUTED_VALUE"""),"10") -> 10 | E14: =IFERROR(__xludf.DUMMYFUNCTION("""COMPUTED_VALUE"""),"B") -> B | F14: =IFERROR(__xludf.DUMMYFUNCTION("""COMPUTED_VALUE"""),"Bhopal") -> Bhopal | G14: =IFERROR(__xludf.DUMMYFUNCTION("""COMPUTED_VALUE"""),90.0) -> 90 | H14: =IFERROR(__xludf.DUMMYFUNCTION("""COMPUTED_VALUE"""),54.0) -> 54 | I14: =IFERROR(__xludf.DUMMYFUNCTION("""COMPUTED_VALUE"""),64.0) -> 64 | J14: =IFERROR(__xludf.DUMMYFUNCTION("""COMPUTED_VALUE"""),49.0) -> 49 | K14: =IFERROR(__xludf.DUMMYFUNCTION("""COMPUTED_VALUE"""),67.0) -> 67 | L14: =IFERROR(__xludf.DUMMYFUNCTION("""COMPUTED_VALUE"""),324.0) -> 324 | M14: =IFERROR(__xludf.DUMMYFUNCTION("""COMPUTED_VALUE"""),64.8) -> 64.8 | N14: =IFERROR(__xludf.DUMMYFUNCTION("""COMPUTED_VALUE"""),76.0) -> 76 | O14: =IFERROR(__xludf.DUMMYFUNCTION("""COMPUTED_VALUE"""),"Pass") -> Pass
A15: =IFERROR(__xludf.DUMMYFUNCTION("""COMPUTED_VALUE"""),"STD-1027") -> STD-1027 | B15: =IFERROR(__xludf.DUMMYFUNCTION("""COMPUTED_VALUE"""),"Ishita Yadav") -> Ishita Yadav | C15: =IFERROR(__xludf.DUMMYFUNCTION("""COMPUTED_VALUE"""),"Female") -> Female | D15: =IFERROR(__xludf.DUMMYFUNCTION("""COMPUTED_VALUE"""),"8") -> 8 | E15: =IFERROR(__xludf.DUMMYFUNCTION("""COMPUTED_VALUE"""),"B") -> B | F15: =IFERROR(__xludf.DUMMYFUNCTION("""COMPUTED_VALUE"""),"Mumbai") -> Mumbai | G15: =IFERROR(__xludf.DUMMYFUNCTION("""COMPUTED_VALUE"""),100.0) -> 100 | H15: =IFERROR(__xludf.DUMMYFUNCTION("""COMPUTED_VALUE"""),49.0) -> 49 | I15: =IFERROR(__xludf.DUMMYFUNCTION("""COMPUTED_VALUE"""),69.0) -> 69 | J15: =IFERROR(__xludf.DUMMYFUNCTION("""COMPUTED_VALUE"""),66.0) -> 66 | K15: =IFERROR(__xludf.DUMMYFUNCTION("""COMPUTED_VALUE"""),72.0) -> 72 | L15: =IFERROR(__xludf.DUMMYFUNCTION("""COMPUTED_VALUE"""),356.0) -> 356 | M15: =IFERROR(__xludf.DUMMYFUNCTION("""COMPUTED_VALUE"""),71.2) -> 71.2 | N15: =IFERROR(__xludf.DUMMYFUNCTION("""COMPUTED_VALUE"""),70.0) -> 70 | O15: =IFERROR(__xludf.DUMMYFUNCTION("""COMPUTED_VALUE"""),"Pass") -> Pass
A16: =IFERROR(__xludf.DUMMYFUNCTION("""COMPUTED_VALUE"""),"STD-1028") -> STD-1028 | B16: =IFERROR(__xludf.DUMMYFUNCTION("""COMPUTED_VALUE"""),"Ritika Nair") -> Ritika Nair | C16: =IFERROR(__xludf.DUMMYFUNCTION("""COMPUTED_VALUE"""),"Female") -> Female | D16: =IFERROR(__xludf.DUMMYFUNCTION("""COMPUTED_VALUE"""),"7") -> 7 | E16: =IFERROR(__xludf.DUMMYFUNCTION("""COMPUTED_VALUE"""),"A") -> A | F16: =IFERROR(__xludf.DUMMYFUNCTION("""COMPUTED_VALUE"""),"Kolkata") -> Kolkata | G16: =IFERROR(__xludf.DUMMYFUNCTION("""COMPUTED_VALUE"""),77.0) -> 77 | H16: =IFERROR(__xludf.DUMMYFUNCTION("""COMPUTED_VALUE"""),72.0) -> 72 | I16: =IFERROR(__xludf.DUMMYFUNCTION("""COMPUTED_VALUE"""),81.0) -> 81 | J16: =IFERROR(__xludf.DUMMYFUNCTION("""COMPUTED_VALUE"""),83.0) -> 83 | K16: =IFERROR(__xludf.DUMMYFUNCTION("""COMPUTED_VALUE"""),76.0) -> 76 | L16: =IFERROR(__xludf.DUMMYFUNCTION("""COMPUTED_VALUE"""),389.0) -> 389 | M16: =IFERROR(__xludf.DUMMYFUNCTION("""COMPUTED_VALUE"""),77.8) -> 77.8 | N16: =IFERROR(__xludf.DUMMYFUNCTION("""COMPUTED_VALUE"""),80.0) -> 80 | O16: =IFERROR(__xludf.DUMMYFUNCTION("""COMPUTED_VALUE"""),"Pass") -> Pass
A17: =IFERROR(__xludf.DUMMYFUNCTION("""COMPUTED_VALUE"""),"STD-1029") -> STD-1029 | B17: =IFERROR(__xludf.DUMMYFUNCTION("""COMPUTED_VALUE"""),"Ananya Patel") -> Ananya Patel | C17: =IFERROR(__xludf.DUMMYFUNCTION("""COMPUTED_VALUE"""),"Female") -> Female | D17: =IFERROR(__xludf.DUMMYFUNCTION("""COMPUTED_VALUE"""),"6") -> 6 | E17: =IFERROR(__xludf.DUMMYFUNCTION("""COMPUTED_VALUE"""),"C") -> C | F17: =IFERROR(__xludf.DUMMYFUNCTION("""COMPUTED_VALUE"""),"Jaipur") -> Jaipur | G17: =IFERROR(__xludf.DUMMYFUNCTION("""COMPUTED_VALUE"""),91.0) -> 91 | H17: =IFERROR(__xludf.DUMMYFUNCTION("""COMPUTED_VALUE"""),91.0) -> 91 | I17: =IFERROR(__xludf.DUMMYFUNCTION("""COMPUTED_VALUE"""),68.0) -> 68 | J17: =IFERROR(__xludf.DUMMYFUNCTION("""COMPUTED_VALUE"""),55.0) -> 55 | K17: =IFERROR(__xludf.DUMMYFUNCTION("""COMPUTED_VALUE"""),94.0) -> 94 | L17: =IFERROR(__xludf.DUMMYFUNCTION("""COMPUTED_VALUE"""),399.0) -> 399 | M17: =IFERROR(__xludf.DUMMYFUNCTION("""COMPUTED_VALUE"""),79.8) -> 79.8 | N17: =IFERROR(__xludf.DUMMYFUNCTION("""COMPUTED_VALUE"""),91.0) -> 91 | O17: =IFERROR(__xludf.DUMMYFUNCTION("""COMPUTED_VALUE"""),"Pass") -> Pass
A18: =IFERROR(__xludf.DUMMYFUNCTION("""COMPUTED_VALUE"""),"STD-1037") -> STD-1037 | B18: =IFERROR(__xludf.DUMMYFUNCTION("""COMPUTED_VALUE"""),"Ananya Das") -> Ananya Das | C18: =IFERROR(__xludf.DUMMYFUNCTION("""COMPUTED_VALUE"""),"Male") -> Male | D18: =IFERROR(__xludf.DUMMYFUNCTION("""COMPUTED_VALUE"""),"10") -> 10 | E18: =IFERROR(__xludf.DUMMYFUNCTION("""COMPUTED_VALUE"""),"A") -> A | F18: =IFERROR(__xludf.DUMMYFUNCTION("""COMPUTED_VALUE"""),"Kolkata") -> Kolkata | G18: =IFERROR(__xludf.DUMMYFUNCTION("""COMPUTED_VALUE"""),92.0) -> 92 | H18: =IFERROR(__xludf.DUMMYFUNCTION("""COMPUTED_VALUE"""),73.0) -> 73 | I18: =IFERROR(__xludf.DUMMYFUNCTION("""COMPUTED_VALUE"""),44.0) -> 44 | J18: =IFERROR(__xludf.DUMMYFUNCTION("""COMPUTED_VALUE"""),45.0) -> 45 | K18: =IFERROR(__xludf.DUMMYFUNCTION("""COMPUTED_VALUE"""),91.0) -> 91 | L18: =IFERROR(__xludf.DUMMYFUNCTION("""COMPUTED_VALUE"""),345.0) -> 345 | M18: =IFERROR(__xludf.DUMMYFUNCTION("""COMPUTED_VALUE"""),69.0) -> 69 | N18: =IFERROR(__xludf.DUMMYFUNCTION("""COMPUTED_VALUE"""),75.0) -> 75 | O18: =IFERROR(__xludf.DUMMYFUNCTION("""COMPUTED_VALUE"""),"Pass") -> Pass
A19: =IFERROR(__xludf.DUMMYFUNCTION("""COMPUTED_VALUE"""),"STD-1038") -> STD-1038 | B19: =IFERROR(__xludf.DUMMYFUNCTION("""COMPUTED_VALUE"""),"Ishita Nair") -> Ishita Nair | C19: =IFERROR(__xludf.DUMMYFUNCTION("""COMPUTED_VALUE"""),"Male") -> Male | D19: =IFERROR(__xludf.DUMMYFUNCTION("""COMPUTED_VALUE"""),"8") -> 8 | E19: =IFERROR(__xludf.DUMMYFUNCTION("""COMPUTED_VALUE"""),"A") -> A | F19: =IFERROR(__xludf.DUMMYFUNCTION("""COMPUTED_VALUE"""),"Mumbai") -> Mumbai | G19: =IFERROR(__xludf.DUMMYFUNCTION("""COMPUTED_VALUE"""),94.0) -> 94 | H19: =IFERROR(__xludf.DUMMYFUNCTION("""COMPUTED_VALUE"""),52.0) -> 52 | I19: =IFERROR(__xludf.DUMMYFUNCTION("""COMPUTED_VALUE"""),54.0) -> 54 | J19: =IFERROR(__xludf.DUMMYFUNCTION("""COMPUTED_VALUE"""),75.0) -> 75 | K19: =IFERROR(__xludf.DUMMYFUNCTION("""COMPUTED_VALUE"""),54.0) -> 54 | L19: =IFERROR(__xludf.DUMMYFUNCTION("""COMPUTED_VALUE"""),329.0) -> 329 | M19: =IFERROR(__xludf.DUMMYFUNCTION("""COMPUTED_VALUE"""),65.8) -> 65.8 | N19: =IFERROR(__xludf.DUMMYFUNCTION("""COMPUTED_VALUE"""),82.0) -> 82 | O19: =IFERROR(__xludf.DUMMYFUNCTION("""COMPUTED_VALUE"""),"Pass") -> Pass
A20: =IFERROR(__xludf.DUMMYFUNCTION("""COMPUTED_VALUE"""),"STD-1043") -> STD-1043 | B20: =IFERROR(__xludf.DUMMYFUNCTION("""COMPUTED_VALUE"""),"Priya Jain") -> Priya Jain | C20: =IFERROR(__xludf.DUMMYFUNCTION("""COMPUTED_VALUE"""),"Male") -> Male | D20: =IFERROR(__xludf.DUMMYFUNCTION("""COMPUTED_VALUE"""),"9") -> 9 | E20: =IFERROR(__xludf.DUMMYFUNCTION("""COMPUTED_VALUE"""),"A") -> A | F20: =IFERROR(__xludf.DUMMYFUNCTION("""COMPUTED_VALUE"""),"Mumbai") -> Mumbai | G20: =IFERROR(__xludf.DUMMYFUNCTION("""COMPUTED_VALUE"""),88.0) -> 88 | H20: =IFERROR(__xludf.DUMMYFUNCTION("""COMPUTED_VALUE"""),98.0) -> 98 | I20: =IFERROR(__xludf.DUMMYFUNCTION("""COMPUTED_VALUE"""),45.0) -> 45 | J20: =IFERROR(__xludf.DUMMYFUNCTION("""COMPUTED_VALUE"""),50.0) -> 50 | K20: =IFERROR(__xludf.DUMMYFUNCTION("""COMPUTED_VALUE"""),53.0) -> 53 | L20: =IFERROR(__xludf.DUMMYFUNCTION("""COMPUTED_VALUE"""),334.0) -> 334 | M20: =IFERROR(__xludf.DUMMYFUNCTION("""COMPUTED_VALUE"""),66.8) -> 66.8 | N20: =IFERROR(__xludf.DUMMYFUNCTION("""COMPUTED_VALUE"""),63.0) -> 63 | O20: =IFERROR(__xludf.DUMMYFUNCTION("""COMPUTED_VALUE"""),"Pass") -> Pass
A21: =IFERROR(__xludf.DUMMYFUNCTION("""COMPUTED_VALUE"""),"STD-1044") -> STD-1044 | B21: =IFERROR(__xludf.DUMMYFUNCTION("""COMPUTED_VALUE"""),"Meera Verma") -> Meera Verma | C21: =IFERROR(__xludf.DUMMYFUNCTION("""COMPUTED_VALUE"""),"Male") -> Male | D21: =IFERROR(__xludf.DUMMYFUNCTION("""COMPUTED_VALUE"""),"6") -> 6 | E21: =IFERROR(__xludf.DUMMYFUNCTION("""COMPUTED_VALUE"""),"C") -> C | F21: =IFERROR(__xludf.DUMMYFUNCTION("""COMPUTED_VALUE"""),"Bhopal") -> Bhopal | G21: =IFERROR(__xludf.DUMMYFUNCTION("""COMPUTED_VALUE"""),85.0) -> 85 | H21: =IFERROR(__xludf.DUMMYFUNCTION("""COMPUTED_VALUE"""),78.0) -> 78 | I21: =IFERROR(__xludf.DUMMYFUNCTION("""COMPUTED_VALUE"""),89.0) -> 89 | J21: =IFERROR(__xludf.DUMMYFUNCTION("""COMPUTED_VALUE"""),52.0) -> 52 | K21: =IFERROR(__xludf.DUMMYFUNCTION("""COMPUTED_VALUE"""),47.0) -> 47 | L21: =IFERROR(__xludf.DUMMYFUNCTION("""COMPUTED_VALUE"""),351.0) -> 351 | M21: =IFERROR(__xludf.DUMMYFUNCTION("""COMPUTED_VALUE"""),70.2) -> 70.2 | N21: =IFERROR(__xludf.DUMMYFUNCTION("""COMPUTED_VALUE"""),78.0) -> 78 | O21: =IFERROR(__xludf.DUMMYFUNCTION("""COMPUTED_VALUE"""),"Pass") -> Pass
A22: =IFERROR(__xludf.DUMMYFUNCTION("""COMPUTED_VALUE"""),"STD-1047") -> STD-1047 | B22: =IFERROR(__xludf.DUMMYFUNCTION("""COMPUTED_VALUE"""),"Arjun Banerjee") -> Arjun Banerjee | C22: =IFERROR(__xludf.DUMMYFUNCTION("""COMPUTED_VALUE"""),"Female") -> Female | D22: =IFERROR(__xludf.DUMMYFUNCTION("""COMPUTED_VALUE"""),"7") -> 7 | E22: =IFERROR(__xludf.DUMMYFUNCTION("""COMPUTED_VALUE"""),"A") -> A | F22: =IFERROR(__xludf.DUMMYFUNCTION("""COMPUTED_VALUE"""),"Kolkata") -> Kolkata | G22: =IFERROR(__xludf.DUMMYFUNCTION("""COMPUTED_VALUE"""),77.0) -> 77 | H22: =IFERROR(__xludf.DUMMYFUNCTION("""COMPUTED_VALUE"""),52.0) -> 52 | I22: =IFERROR(__xludf.DUMMYFUNCTION("""COMPUTED_VALUE"""),45.0) -> 45 | J22: =IFERROR(__xludf.DUMMYFUNCTION("""COMPUTED_VALUE"""),81.0) -> 81 | K22: =IFERROR(__xludf.DUMMYFUNCTION("""COMPUTED_VALUE"""),57.0) -> 57 | L22: =IFERROR(__xludf.DUMMYFUNCTION("""COMPUTED_VALUE"""),312.0) -> 312 | M22: =IFERROR(__xludf.DUMMYFUNCTION("""COMPUTED_VALUE"""),62.4) -> 62.4 | N22: =IFERROR(__xludf.DUMMYFUNCTION("""COMPUTED_VALUE"""),91.0) -> 91 | O22: =IFERROR(__xludf.DUMMYFUNCTION("""COMPUTED_VALUE"""),"Pass") -> Pass
A23: =IFERROR(__xludf.DUMMYFUNCTION("""COMPUTED_VALUE"""),"STD-1055") -> STD-1055 | B23: =IFERROR(__xludf.DUMMYFUNCTION("""COMPUTED_VALUE"""),"Shreya Singh") -> Shreya Singh | C23: =IFERROR(__xludf.DUMMYFUNCTION("""COMPUTED_VALUE"""),"Female") -> Female | D23: =IFERROR(__xludf.DUMMYFUNCTION("""COMPUTED_VALUE"""),"9") -> 9 | E23: =IFERROR(__xludf.DUMMYFUNCTION("""COMPUTED_VALUE"""),"B") -> B | F23: =IFERROR(__xludf.DUMMYFUNCTION("""COMPUTED_VALUE"""),"Jaipur") -> Jaipur | G23: =IFERROR(__xludf.DUMMYFUNCTION("""COMPUTED_VALUE"""),92.0) -> 92 | H23: =IFERROR(__xludf.DUMMYFUNCTION("""COMPUTED_VALUE"""),71.0) -> 71 | I23: =IFERROR(__xludf.DUMMYFUNCTION("""COMPUTED_VALUE"""),71.0) -> 71 | J23: =IFERROR(__xludf.DUMMYFUNCTION("""COMPUTED_VALUE"""),81.0) -> 81 | K23: =IFERROR(__xludf.DUMMYFUNCTION("""COMPUTED_VALUE"""),100.0) -> 100 | L23: =IFERROR(__xludf.DUMMYFUNCTION("""COMPUTED_VALUE"""),415.0) -> 415 | M23: =IFERROR(__xludf.DUMMYFUNCTION("""COMPUTED_VALUE"""),83.0) -> 83 | N23: =IFERROR(__xludf.DUMMYFUNCTION("""COMPUTED_VALUE"""),60.0) -> 60 | O23: =IFERROR(__xludf.DUMMYFUNCTION("""COMPUTED_VALUE"""),"Pass") -> Pass
A24: =IFERROR(__xludf.DUMMYFUNCTION("""COMPUTED_VALUE"""),"STD-1058") -> STD-1058 | B24: =IFERROR(__xludf.DUMMYFUNCTION("""COMPUTED_VALUE"""),"Sneha Gupta") -> Sneha Gupta | C24: =IFERROR(__xludf.DUMMYFUNCTION("""COMPUTED_VALUE"""),"Female") -> Female | D24: =IFERROR(__xludf.DUMMYFUNCTION("""COMPUTED_VALUE"""),"8") -> 8 | E24: =IFERROR(__xludf.DUMMYFUNCTION("""COMPUTED_VALUE"""),"B") -> B | F24: =IFERROR(__xludf.DUMMYFUNCTION("""COMPUTED_VALUE"""),"Patna") -> Patna | G24: =IFERROR(__xludf.DUMMYFUNCTION("""COMPUTED_VALUE"""),76.0) -> 76 | H24: =IFERROR(__xludf.DUMMYFUNCTION("""COMPUTED_VALUE"""),71.0) -> 71 | I24: =IFERROR(__xludf.DUMMYFUNCTION("""COMPUTED_VALUE"""),46.0) -> 46 | J24: =IFERROR(__xludf.DUMMYFUNCTION("""COMPUTED_VALUE"""),47.0) -> 47 | K24: =IFERROR(__xludf.DUMMYFUNCTION("""COMPUTED_VALUE"""),66.0) -> 66 | L24: =IFERROR(__xludf.DUMMYFUNCTION("""COMPUTED_VALUE"""),306.0) -> 306 | M24: =IFERROR(__xludf.DUMMYFUNCTION("""COMPUTED_VALUE"""),61.2) -> 61.2 | N24: =IFERROR(__xludf.DUMMYFUNCTION("""COMPUTED_VALUE"""),98.0) -> 98 | O24: =IFERROR(__xludf.DUMMYFUNCTION("""COMPUTED_VALUE"""),"Pass") -> Pass
A25: =IFERROR(__xludf.DUMMYFUNCTION("""COMPUTED_VALUE"""),"STD-1059") -> STD-1059 | B25: =IFERROR(__xludf.DUMMYFUNCTION("""COMPUTED_VALUE"""),"Ananya Iyer") -> Ananya Iyer | C25: =IFERROR(__xludf.DUMMYFUNCTION("""COMPUTED_VALUE"""),"Female") -> Female | D25: =IFERROR(__xludf.DUMMYFUNCTION("""COMPUTED_VALUE"""),"9") -> 9 | E25: =IFERROR(__xludf.DUMMYFUNCTION("""COMPUTED_VALUE"""),"A") -> A | F25: =IFERROR(__xludf.DUMMYFUNCTION("""COMPUTED_VALUE"""),"Patna") -> Patna | G25: =IFERROR(__xludf.DUMMYFUNCTION("""COMPUTED_VALUE"""),95.0) -> 95 | H25: =IFERROR(__xludf.DUMMYFUNCTION("""COMPUTED_VALUE"""),86.0) -> 86 | I25: =IFERROR(__xludf.DUMMYFUNCTION("""COMPUTED_VALUE"""),87.0) -> 87 | J25: =IFERROR(__xludf.DUMMYFUNCTION("""COMPUTED_VALUE"""),42.0) -> 42 | K25: =IFERROR(__xludf.DUMMYFUNCTION("""COMPUTED_VALUE"""),67.0) -> 67 | L25: =IFERROR(__xludf.DUMMYFUNCTION("""COMPUTED_VALUE"""),377.0) -> 377 | M25: =IFERROR(__xludf.DUMMYFUNCTION("""COMPUTED_VALUE"""),75.4) -> 75.4 | N25: =IFERROR(__xludf.DUMMYFUNCTION("""COMPUTED_VALUE"""),77.0) -> 77 | O25: =IFERROR(__xludf.DUMMYFUNCTION("""COMPUTED_VALUE"""),"Pass") -> Pass
A26: =IFERROR(__xludf.DUMMYFUNCTION("""COMPUTED_VALUE"""),"STD-1060") -> STD-1060 | B26: =IFERROR(__xludf.DUMMYFUNCTION("""COMPUTED_VALUE"""),"Ishita Banerjee") -> Ishita Banerjee | C26: =IFERROR(__xludf.DUMMYFUNCTION("""COMPUTED_VALUE"""),"Male") -> Male | D26: =IFERROR(__xludf.DUMMYFUNCTION("""COMPUTED_VALUE"""),"7") -> 7 | E26: =IFERROR(__xludf.DUMMYFUNCTION("""COMPUTED_VALUE"""),"A") -> A | F26: =IFERROR(__xludf.DUMMYFUNCTION("""COMPUTED_VALUE"""),"Bhopal") -> Bhopal | G26: =IFERROR(__xludf.DUMMYFUNCTION("""COMPUTED_VALUE"""),91.0) -> 91 | H26: =IFERROR(__xludf.DUMMYFUNCTION("""COMPUTED_VALUE"""),50.0) -> 50 | I26: =IFERROR(__xludf.DUMMYFUNCTION("""COMPUTED_VALUE"""),70.0) -> 70 | J26: =IFERROR(__xludf.DUMMYFUNCTION("""COMPUTED_VALUE"""),57.0) -> 57 | K26: =IFERROR(__xludf.DUMMYFUNCTION("""COMPUTED_VALUE"""),79.0) -> 79 | L26: =IFERROR(__xludf.DUMMYFUNCTION("""COMPUTED_VALUE"""),347.0) -> 347 | M26: =IFERROR(__xludf.DUMMYFUNCTION("""COMPUTED_VALUE"""),69.4) -> 69.4 | N26: =IFERROR(__xludf.DUMMYFUNCTION("""COMPUTED_VALUE"""),83.0) -> 83 | O26: =IFERROR(__xludf.DUMMYFUNCTION("""COMPUTED_VALUE"""),"Pass") -> Pass
A27: =IFERROR(__xludf.DUMMYFUNCTION("""COMPUTED_VALUE"""),"STD-1061") -> STD-1061 | B27: =IFERROR(__xludf.DUMMYFUNCTION("""COMPUTED_VALUE"""),"Ritika Kulkarni") -> Ritika Kulkarni | C27: =IFERROR(__xludf.DUMMYFUNCTION("""COMPUTED_VALUE"""),"Female") -> Female | D27: =IFERROR(__xludf.DUMMYFUNCTION("""COMPUTED_VALUE"""),"7") -> 7 | E27: =IFERROR(__xludf.DUMMYFUNCTION("""COMPUTED_VALUE"""),"A") -> A | F27: =IFERROR(__xludf.DUMMYFUNCTION("""COMPUTED_VALUE"""),"Delhi") -> Delhi | G27: =IFERROR(__xludf.DUMMYFUNCTION("""COMPUTED_VALUE"""),87.0) -> 87 | H27: =IFERROR(__xludf.DUMMYFUNCTION("""COMPUTED_VALUE"""),58.0) -> 58 | I27: =IFERROR(__xludf.DUMMYFUNCTION("""COMPUTED_VALUE"""),70.0) -> 70 | J27: =IFERROR(__xludf.DUMMYFUNCTION("""COMPUTED_VALUE"""),94.0) -> 94 | K27: =IFERROR(__xludf.DUMMYFUNCTION("""COMPUTED_VALUE"""),50.0) -> 50 | L27: =IFERROR(__xludf.DUMMYFUNCTION("""COMPUTED_VALUE"""),359.0) -> 359 | M27: =IFERROR(__xludf.DUMMYFUNCTION("""COMPUTED_VALUE"""),71.8) -> 71.8 | N27: =IFERROR(__xludf.DUMMYFUNCTION("""COMPUTED_VALUE"""),100.0) -> 100 | O27: =IFERROR(__xludf.DUMMYFUNCTION("""COMPUTED_VALUE"""),"Pass") -> Pass
A28: =IFERROR(__xludf.DUMMYFUNCTION("""COMPUTED_VALUE"""),"STD-1062") -> STD-1062 | B28: =IFERROR(__xludf.DUMMYFUNCTION("""COMPUTED_VALUE"""),"Karan Choudhary") -> Karan Choudhary | C28: =IFERROR(__xludf.DUMMYFUNCTION("""COMPUTED_VALUE"""),"Female") -> Female | D28: =IFERROR(__xludf.DUMMYFUNCTION("""COMPUTED_VALUE"""),"8") -> 8 | E28: =IFERROR(__xludf.DUMMYFUNCTION("""COMPUTED_VALUE"""),"B") -> B | F28: =IFERROR(__xludf.DUMMYFUNCTION("""COMPUTED_VALUE"""),"Jaipur") -> Jaipur | G28: =IFERROR(__xludf.DUMMYFUNCTION("""COMPUTED_VALUE"""),85.0) -> 85 | H28: =IFERROR(__xludf.DUMMYFUNCTION("""COMPUTED_VALUE"""),84.0) -> 84 | I28: =IFERROR(__xludf.DUMMYFUNCTION("""COMPUTED_VALUE"""),83.0) -> 83 | J28: =IFERROR(__xludf.DUMMYFUNCTION("""COMPUTED_VALUE"""),98.0) -> 98 | K28: =IFERROR(__xludf.DUMMYFUNCTION("""COMPUTED_VALUE"""),79.0) -> 79 | L28: =IFERROR(__xludf.DUMMYFUNCTION("""COMPUTED_VALUE"""),429.0) -> 429 | M28: =IFERROR(__xludf.DUMMYFUNCTION("""COMPUTED_VALUE"""),85.8) -> 85.8 | N28: =IFERROR(__xludf.DUMMYFUNCTION("""COMPUTED_VALUE"""),100.0) -> 100 | O28: =IFERROR(__xludf.DUMMYFUNCTION("""COMPUTED_VALUE"""),"Pass") -> Pass
A29: =IFERROR(__xludf.DUMMYFUNCTION("""COMPUTED_VALUE"""),"STD-1063") -> STD-1063 | B29: =IFERROR(__xludf.DUMMYFUNCTION("""COMPUTED_VALUE"""),"Karan Sharma") -> Karan Sharma | C29: =IFERROR(__xludf.DUMMYFUNCTION("""COMPUTED_VALUE"""),"Female") -> Female | D29: =IFERROR(__xludf.DUMMYFUNCTION("""COMPUTED_VALUE"""),"7") -> 7 | E29: =IFERROR(__xludf.DUMMYFUNCTION("""COMPUTED_VALUE"""),"C") -> C | F29: =IFERROR(__xludf.DUMMYFUNCTION("""COMPUTED_VALUE"""),"Patna") -> Patna | G29: =IFERROR(__xludf.DUMMYFUNCTION("""COMPUTED_VALUE"""),76.0) -> 76 | H29: =IFERROR(__xludf.DUMMYFUNCTION("""COMPUTED_VALUE"""),91.0) -> 91 | I29: =IFERROR(__xludf.DUMMYFUNCTION("""COMPUTED_VALUE"""),71.0) -> 71 | J29: =IFERROR(__xludf.DUMMYFUNCTION("""COMPUTED_VALUE"""),71.0) -> 71 | K29: =IFERROR(__xludf.DUMMYFUNCTION("""COMPUTED_VALUE"""),80.0) -> 80 | L29: =IFERROR(__xludf.DUMMYFUNCTION("""COMPUTED_VALUE"""),389.0) -> 389 | M29: =IFERROR(__xludf.DUMMYFUNCTION("""COMPUTED_VALUE"""),77.8) -> 77.8 | N29: =IFERROR(__xludf.DUMMYFUNCTION("""COMPUTED_VALUE"""),64.0) -> 64 | O29: =IFERROR(__xludf.DUMMYFUNCTION("""COMPUTED_VALUE"""),"Pass") -> Pass
A30: =IFERROR(__xludf.DUMMYFUNCTION("""COMPUTED_VALUE"""),"STD-1066") -> STD-1066 | B30: =IFERROR(__xludf.DUMMYFUNCTION("""COMPUTED_VALUE"""),"Kavya Yadav") -> Kavya Yadav | C30: =IFERROR(__xludf.DUMMYFUNCTION("""COMPUTED_VALUE"""),"Female") -> Female | D30: =IFERROR(__xludf.DUMMYFUNCTION("""COMPUTED_VALUE"""),"10") -> 10 | E30: =IFERROR(__xludf.DUMMYFUNCTION("""COMPUTED_VALUE"""),"B") -> B | F30: =IFERROR(__xludf.DUMMYFUNCTION("""COMPUTED_VALUE"""),"Jaipur") -> Jaipur | G30: =IFERROR(__xludf.DUMMYFUNCTION("""COMPUTED_VALUE"""),88.0) -> 88 | H30: =IFERROR(__xludf.DUMMYFUNCTION("""COMPUTED_VALUE"""),75.0) -> 75 | I30: =IFERROR(__xludf.DUMMYFUNCTION("""COMPUTED_VALUE"""),77.0) -> 77 | J30: =IFERROR(__xludf.DUMMYFUNCTION("""COMPUTED_VALUE"""),41.0) -> 41 | K30: =IFERROR(__xludf.DUMMYFUNCTION("""COMPUTED_VALUE"""),84.0) -> 84 | L30: =IFERROR(__xludf.DUMMYFUNCTION("""COMPUTED_VALUE"""),365.0) -> 365 | M30: =IFERROR(__xludf.DUMMYFUNCTION("""COMPUTED_VALUE"""),73.0) -> 73 | N30: =IFERROR(__xludf.DUMMYFUNCTION("""COMPUTED_VALUE"""),61.0) -> 61 | O30: =IFERROR(__xludf.DUMMYFUNCTION("""COMPUTED_VALUE"""),"Pass") -> Pass
A31: =IFERROR(__xludf.DUMMYFUNCTION("""COMPUTED_VALUE"""),"STD-1067") -> STD-1067 | B31: =IFERROR(__xludf.DUMMYFUNCTION("""COMPUTED_VALUE"""),"Sneha Yadav") -> Sneha Yadav | C31: =IFERROR(__xludf.DUMMYFUNCTION("""COMPUTED_VALUE"""),"Male") -> Male | D31: =IFERROR(__xludf.DUMMYFUNCTION("""COMPUTED_VALUE"""),"9") -> 9 | E31: =IFERROR(__xludf.DUMMYFUNCTION("""COMPUTED_VALUE"""),"C") -> C | F31: =IFERROR(__xludf.DUMMYFUNCTION("""COMPUTED_VALUE"""),"Delhi") -> Delhi | G31: =IFERROR(__xludf.DUMMYFUNCTION("""COMPUTED_VALUE"""),98.0) -> 98 | H31: =IFERROR(__xludf.DUMMYFUNCTION("""COMPUTED_VALUE"""),43.0) -> 43 | I31: =IFERROR(__xludf.DUMMYFUNCTION("""COMPUTED_VALUE"""),70.0) -> 70 | J31: =IFERROR(__xludf.DUMMYFUNCTION("""COMPUTED_VALUE"""),41.0) -> 41 | K31: =IFERROR(__xludf.DUMMYFUNCTION("""COMPUTED_VALUE"""),94.0) -> 94 | L31: =IFERROR(__xludf.DUMMYFUNCTION("""COMPUTED_VALUE"""),346.0) -> 346 | M31: =IFERROR(__xludf.DUMMYFUNCTION("""COMPUTED_VALUE"""),69.2) -> 69.2 | N31: =IFERROR(__xludf.DUMMYFUNCTION("""COMPUTED_VALUE"""),67.0) -> 67 | O31: =IFERROR(__xludf.DUMMYFUNCTION("""COMPUTED_VALUE"""),"Pass") -> Pass
A32: =IFERROR(__xludf.DUMMYFUNCTION("""COMPUTED_VALUE"""),"STD-1069") -> STD-1069 | B32: =IFERROR(__xludf.DUMMYFUNCTION("""COMPUTED_VALUE"""),"Pooja Kulkarni") -> Pooja Kulkarni | C32: =IFERROR(__xludf.DUMMYFUNCTION("""COMPUTED_VALUE"""),"Female") -> Female | D32: =IFERROR(__xludf.DUMMYFUNCTION("""COMPUTED_VALUE"""),"8") -> 8 | E32: =IFERROR(__xludf.DUMMYFUNCTION("""COMPUTED_VALUE"""),"A") -> A | F32: =IFERROR(__xludf.DUMMYFUNCTION("""COMPUTED_VALUE"""),"Patna") -> Patna | G32: =IFERROR(__xludf.DUMMYFUNCTION("""COMPUTED_VALUE"""),82.0) -> 82 | H32: =IFERROR(__xludf.DUMMYFUNCTION("""COMPUTED_VALUE"""),56.0) -> 56 | I32: =IFERROR(__xludf.DUMMYFUNCTION("""COMPUTED_VALUE"""),73.0) -> 73 | J32: =IFERROR(__xludf.DUMMYFUNCTION("""COMPUTED_VALUE"""),80.0) -> 80 | K32: =IFERROR(__xludf.DUMMYFUNCTION("""COMPUTED_VALUE"""),47.0) -> 47 | L32: =IFERROR(__xludf.DUMMYFUNCTION("""COMPUTED_VALUE"""),338.0) -> 338 | M32: =IFERROR(__xludf.DUMMYFUNCTION("""COMPUTED_VALUE"""),67.6) -> 67.6 | N32: =IFERROR(__xludf.DUMMYFUNCTION("""COMPUTED_VALUE"""),100.0) -> 100 | O32: =IFERROR(__xludf.DUMMYFUNCTION("""COMPUTED_VALUE"""),"Pass") -> Pass
A33: =IFERROR(__xludf.DUMMYFUNCTION("""COMPUTED_VALUE"""),"STD-1073") -> STD-1073 | B33: =IFERROR(__xludf.DUMMYFUNCTION("""COMPUTED_VALUE"""),"Neha Patel") -> Neha Patel | C33: =IFERROR(__xludf.DUMMYFUNCTION("""COMPUTED_VALUE"""),"Female") -> Female | D33: =IFERROR(__xludf.DUMMYFUNCTION("""COMPUTED_VALUE"""),"10") -> 10 | E33: =IFERROR(__xludf.DUMMYFUNCTION("""COMPUTED_VALUE"""),"C") -> C | F33: =IFERROR(__xludf.DUMMYFUNCTION("""COMPUTED_VALUE"""),"Mumbai") -> Mumbai | G33: =IFERROR(__xludf.DUMMYFUNCTION("""COMPUTED_VALUE"""),87.0) -> 87 | H33: =IFERROR(__xludf.DUMMYFUNCTION("""COMPUTED_VALUE"""),60.0) -> 60 | I33: =IFERROR(__xludf.DUMMYFUNCTION("""COMPUTED_VALUE"""),71.0) -> 71 | J33: =IFERROR(__xludf.DUMMYFUNCTION("""COMPUTED_VALUE"""),91.0) -> 91 | K33: =IFERROR(__xludf.DUMMYFUNCTION("""COMPUTED_VALUE"""),42.0) -> 42 | L33: =IFERROR(__xludf.DUMMYFUNCTION("""COMPUTED_VALUE"""),351.0) -> 351 | M33: =IFERROR(__xludf.DUMMYFUNCTION("""COMPUTED_VALUE"""),70.2) -> 70.2 | N33: =IFERROR(__xludf.DUMMYFUNCTION("""COMPUTED_VALUE"""),79.0) -> 79 | O33: =IFERROR(__xludf.DUMMYFUNCTION("""COMPUTED_VALUE"""),"Pass") -> Pass
A34: =IFERROR(__xludf.DUMMYFUNCTION("""COMPUTED_VALUE"""),"STD-1074") -> STD-1074 | B34: =IFERROR(__xludf.DUMMYFUNCTION("""COMPUTED_VALUE"""),"Pooja Verma") -> Pooja Verma | C34: =IFERROR(__xludf.DUMMYFUNCTION("""COMPUTED_VALUE"""),"Female") -> Female | D34: =IFERROR(__xludf.DUMMYFUNCTION("""COMPUTED_VALUE"""),"9") -> 9 | E34: =IFERROR(__xludf.DUMMYFUNCTION("""COMPUTED_VALUE"""),"A") -> A | F34: =IFERROR(__xludf.DUMMYFUNCTION("""COMPUTED_VALUE"""),"Bhopal") -> Bhopal | G34: =IFERROR(__xludf.DUMMYFUNCTION("""COMPUTED_VALUE"""),88.0) -> 88 | H34: =IFERROR(__xludf.DUMMYFUNCTION("""COMPUTED_VALUE"""),88.0) -> 88 | I34: =IFERROR(__xludf.DUMMYFUNCTION("""COMPUTED_VALUE"""),40.0) -> 40 | J34: =IFERROR(__xludf.DUMMYFUNCTION("""COMPUTED_VALUE"""),100.0) -> 100 | K34: =IFERROR(__xludf.DUMMYFUNCTION("""COMPUTED_VALUE"""),78.0) -> 78 | L34: =IFERROR(__xludf.DUMMYFUNCTION("""COMPUTED_VALUE"""),394.0) -> 394 | M34: =IFERROR(__xludf.DUMMYFUNCTION("""COMPUTED_VALUE"""),78.8) -> 78.8 | N34: =IFERROR(__xludf.DUMMYFUNCTION("""COMPUTED_VALUE"""),64.0) -> 64 | O34: =IFERROR(__xludf.DUMMYFUNCTION("""COMPUTED_VALUE"""),"Pass") -> Pass
A35: =IFERROR(__xludf.DUMMYFUNCTION("""COMPUTED_VALUE"""),"STD-1078") -> STD-1078 | B35: =IFERROR(__xludf.DUMMYFUNCTION("""COMPUTED_VALUE"""),"Kavya Reddy") -> Kavya Reddy | C35: =IFERROR(__xludf.DUMMYFUNCTION("""COMPUTED_VALUE"""),"Female") -> Female | D35: =IFERROR(__xludf.DUMMYFUNCTION("""COMPUTED_VALUE"""),"10") -> 10 | E35: =IFERROR(__xludf.DUMMYFUNCTION("""COMPUTED_VALUE"""),"A") -> A | F35: =IFERROR(__xludf.DUMMYFUNCTION("""COMPUTED_VALUE"""),"Lucknow") -> Lucknow | G35: =IFERROR(__xludf.DUMMYFUNCTION("""COMPUTED_VALUE"""),84.0) -> 84 | H35: =IFERROR(__xludf.DUMMYFUNCTION("""COMPUTED_VALUE"""),91.0) -> 91 | I35: =IFERROR(__xludf.DUMMYFUNCTION("""COMPUTED_VALUE"""),96.0) -> 96 | J35: =IFERROR(__xludf.DUMMYFUNCTION("""COMPUTED_VALUE"""),54.0) -> 54 | K35: =IFERROR(__xludf.DUMMYFUNCTION("""COMPUTED_VALUE"""),89.0) -> 89 | L35: =IFERROR(__xludf.DUMMYFUNCTION("""COMPUTED_VALUE"""),414.0) -> 414 | M35: =IFERROR(__xludf.DUMMYFUNCTION("""COMPUTED_VALUE"""),82.8) -> 82.8 | N35: =IFERROR(__xludf.DUMMYFUNCTION("""COMPUTED_VALUE"""),71.0) -> 71 | O35: =IFERROR(__xludf.DUMMYFUNCTION("""COMPUTED_VALUE"""),"Pass") -> Pass
A36: =IFERROR(__xludf.DUMMYFUNCTION("""COMPUTED_VALUE"""),"STD-1080") -> STD-1080 | B36: =IFERROR(__xludf.DUMMYFUNCTION("""COMPUTED_VALUE"""),"Aarav Sharma") -> Aarav Sharma | C36: =IFERROR(__xludf.DUMMYFUNCTION("""COMPUTED_VALUE"""),"Female") -> Female | D36: =IFERROR(__xludf.DUMMYFUNCTION("""COMPUTED_VALUE"""),"7") -> 7 | E36: =IFERROR(__xludf.DUMMYFUNCTION("""COMPUTED_VALUE"""),"B") -> B | F36: =IFERROR(__xludf.DUMMYFUNCTION("""COMPUTED_VALUE"""),"Kolkata") -> Kolkata | G36: =IFERROR(__xludf.DUMMYFUNCTION("""COMPUTED_VALUE"""),96.0) -> 96 | H36: =IFERROR(__xludf.DUMMYFUNCTION("""COMPUTED_VALUE"""),43.0) -> 43 | I36: =IFERROR(__xludf.DUMMYFUNCTION("""COMPUTED_VALUE"""),88.0) -> 88 | J36: =IFERROR(__xludf.DUMMYFUNCTION("""COMPUTED_VALUE"""),55.0) -> 55 | K36: =IFERROR(__xludf.DUMMYFUNCTION("""COMPUTED_VALUE"""),56.0) -> 56 | L36: =IFERROR(__xludf.DUMMYFUNCTION("""COMPUTED_VALUE"""),338.0) -> 338 | M36: =IFERROR(__xludf.DUMMYFUNCTION("""COMPUTED_VALUE"""),67.6) -> 67.6 | N36: =IFERROR(__xludf.DUMMYFUNCTION("""COMPUTED_VALUE"""),93.0) -> 93 | O36: =IFERROR(__xludf.DUMMYFUNCTION("""COMPUTED_VALUE"""),"Pass") -> Pass
A37: =IFERROR(__xludf.DUMMYFUNCTION("""COMPUTED_VALUE"""),"STD-1086") -> STD-1086 | B37: =IFERROR(__xludf.DUMMYFUNCTION("""COMPUTED_VALUE"""),"Sai Yadav") -> Sai Yadav | C37: =IFERROR(__xludf.DUMMYFUNCTION("""COMPUTED_VALUE"""),"Male") -> Male | D37: =IFERROR(__xludf.DUMMYFUNCTION("""COMPUTED_VALUE"""),"9") -> 9 | E37: =IFERROR(__xludf.DUMMYFUNCTION("""COMPUTED_VALUE"""),"B") -> B | F37: =IFERROR(__xludf.DUMMYFUNCTION("""COMPUTED_VALUE"""),"Kolkata") -> Kolkata | G37: =IFERROR(__xludf.DUMMYFUNCTION("""COMPUTED_VALUE"""),84.0) -> 84 | H37: =IFERROR(__xludf.DUMMYFUNCTION("""COMPUTED_VALUE"""),91.0) -> 91 | I37: =IFERROR(__xludf.DUMMYFUNCTION("""COMPUTED_VALUE"""),97.0) -> 97 | J37: =IFERROR(__xludf.DUMMYFUNCTION("""COMPUTED_VALUE"""),73.0) -> 73 | K37: =IFERROR(__xludf.DUMMYFUNCTION("""COMPUTED_VALUE"""),53.0) -> 53 | L37: =IFERROR(__xludf.DUMMYFUNCTION("""COMPUTED_VALUE"""),398.0) -> 398 | M37: =IFERROR(__xludf.DUMMYFUNCTION("""COMPUTED_VALUE"""),79.6) -> 79.6 | N37: =IFERROR(__xludf.DUMMYFUNCTION("""COMPUTED_VALUE"""),60.0) -> 60 | O37: =IFERROR(__xludf.DUMMYFUNCTION("""COMPUTED_VALUE"""),"Pass") -> Pass
A38: =IFERROR(__xludf.DUMMYFUNCTION("""COMPUTED_VALUE"""),"STD-1087") -> STD-1087 | B38: =IFERROR(__xludf.DUMMYFUNCTION("""COMPUTED_VALUE"""),"Simran Verma") -> Simran Verma | C38: =IFERROR(__xludf.DUMMYFUNCTION("""COMPUTED_VALUE"""),"Female") -> Female | D38: =IFERROR(__xludf.DUMMYFUNCTION("""COMPUTED_VALUE"""),"6") -> 6 | E38: =IFERROR(__xludf.DUMMYFUNCTION("""COMPUTED_VALUE"""),"B") -> B | F38: =IFERROR(__xludf.DUMMYFUNCTION("""COMPUTED_VALUE"""),"Delhi") -> Delhi | G38: =IFERROR(__xludf.DUMMYFUNCTION("""COMPUTED_VALUE"""),85.0) -> 85 | H38: =IFERROR(__xludf.DUMMYFUNCTION("""COMPUTED_VALUE"""),42.0) -> 42 | I38: =IFERROR(__xludf.DUMMYFUNCTION("""COMPUTED_VALUE"""),72.0) -> 72 | J38: =IFERROR(__xludf.DUMMYFUNCTION("""COMPUTED_VALUE"""),60.0) -> 60 | K38: =IFERROR(__xludf.DUMMYFUNCTION("""COMPUTED_VALUE"""),81.0) -> 81 | L38: =IFERROR(__xludf.DUMMYFUNCTION("""COMPUTED_VALUE"""),340.0) -> 340 | M38: =IFERROR(__xludf.DUMMYFUNCTION("""COMPUTED_VALUE"""),68.0) -> 68 | N38: =IFERROR(__xludf.DUMMYFUNCTION("""COMPUTED_VALUE"""),84.0) -> 84 | O38: =IFERROR(__xludf.DUMMYFUNCTION("""COMPUTED_VALUE"""),"Pass") -> Pass
A39: =IFERROR(__xludf.DUMMYFUNCTION("""COMPUTED_VALUE"""),"STD-1088") -> STD-1088 | B39: =IFERROR(__xludf.DUMMYFUNCTION("""COMPUTED_VALUE"""),"Pooja Kulkarni") -> Pooja Kulkarni | C39: =IFERROR(__xludf.DUMMYFUNCTION("""COMPUTED_VALUE"""),"Female") -> Female | D39: =IFERROR(__xludf.DUMMYFUNCTION("""COMPUTED_VALUE"""),"6") -> 6 | E39: =IFERROR(__xludf.DUMMYFUNCTION("""COMPUTED_VALUE"""),"B") -> B | F39: =IFERROR(__xludf.DUMMYFUNCTION("""COMPUTED_VALUE"""),"Delhi") -> Delhi | G39: =IFERROR(__xludf.DUMMYFUNCTION("""COMPUTED_VALUE"""),84.0) -> 84 | H39: =IFERROR(__xludf.DUMMYFUNCTION("""COMPUTED_VALUE"""),80.0) -> 80 | I39: =IFERROR(__xludf.DUMMYFUNCTION("""COMPUTED_VALUE"""),58.0) -> 58 | J39: =IFERROR(__xludf.DUMMYFUNCTION("""COMPUTED_VALUE"""),88.0) -> 88 | K39: =IFERROR(__xludf.DUMMYFUNCTION("""COMPUTED_VALUE"""),90.0) -> 90 | L39: =IFERROR(__xludf.DUMMYFUNCTION("""COMPUTED_VALUE"""),400.0) -> 400 | M39: =IFERROR(__xludf.DUMMYFUNCTION("""COMPUTED_VALUE"""),80.0) -> 80 | N39: =IFERROR(__xludf.DUMMYFUNCTION("""COMPUTED_VALUE"""),63.0) -> 63 | O39: =IFERROR(__xludf.DUMMYFUNCTION("""COMPUTED_VALUE"""),"Pass") -> Pass
A40: =IFERROR(__xludf.DUMMYFUNCTION("""COMPUTED_VALUE"""),"STD-1090") -> STD-1090 | B40: =IFERROR(__xludf.DUMMYFUNCTION("""COMPUTED_VALUE"""),"Rahul Reddy") -> Rahul Reddy | C40: =IFERROR(__xludf.DUMMYFUNCTION("""COMPUTED_VALUE"""),"Male") -> Male | D40: =IFERROR(__xludf.DUMMYFUNCTION("""COMPUTED_VALUE"""),"10") -> 10 | E40: =IFERROR(__xludf.DUMMYFUNCTION("""COMPUTED_VALUE"""),"C") -> C | F40: =IFERROR(__xludf.DUMMYFUNCTION("""COMPUTED_VALUE"""),"Jaipur") -> Jaipur | G40: =IFERROR(__xludf.DUMMYFUNCTION("""COMPUTED_VALUE"""),85.0) -> 85 | H40: =IFERROR(__xludf.DUMMYFUNCTION("""COMPUTED_VALUE"""),68.0) -> 68 | I40: =IFERROR(__xludf.DUMMYFUNCTION("""COMPUTED_VALUE"""),41.0) -> 41 | J40: =IFERROR(__xludf.DUMMYFUNCTION("""COMPUTED_VALUE"""),88.0) -> 88 | K40: =IFERROR(__xludf.DUMMYFUNCTION("""COMPUTED_VALUE"""),75.0) -> 75 | L40: =IFERROR(__xludf.DUMMYFUNCTION("""COMPUTED_VALUE"""),357.0) -> 357 | M40: =IFERROR(__xludf.DUMMYFUNCTION("""COMPUTED_VALUE"""),71.4) -> 71.4 | N40: =IFERROR(__xludf.DUMMYFUNCTION("""COMPUTED_VALUE"""),91.0) -> 91 | O40: =IFERROR(__xludf.DUMMYFUNCTION("""COMPUTED_VALUE"""),"Pass") -> Pass
...

Sheet Q5
A1: {='Questions Answers'!A6} -> 5. Find how many students have Attendance greater than 90%.
